<?xml version="1.0"?>


<robot name="my_robot"
    xmlns:xacro="http://www.ros.org/wiki/xacro">
    <xacro:include filename="$(find my_robot)/urdf/moovy.gazebo" />
    <gazebo reference="base_link">
        <material>Gazebo/Blue</material>
    </gazebo>

    <gazebo reference="front_left_wheel">
        <material>Gazebo/Black</material>
    </gazebo>


    <gazebo reference="front_right_wheel">
        <material>Gazebo/Black</material>
    </gazebo>

    <gazebo reference="back_left_wheel">
        <material>Gazebo/Black</material>
    </gazebo>

    <gazebo reference="back_right_wheel">
        <material>Gazebo/Black</material>
    </gazebo>


    <gazebo reference="camera_link">
        <material>Gazebo/Black</material>
    </gazebo>

    <gazebo reference="front_ultrasonic_link">
        <material>Gazebo/Black</material>
    </gazebo>

    <gazebo reference="left_ultrasonic_link">
        <material>Gazebo/Black</material>
    </gazebo>
    <gazebo reference="realsense_link">
        <material>Gazebo/Black</material>
    </gazebo>
    <link name="robot_footprint">
    </link>

    <link name="base_link">
        <origin xyz="0 0 0" rpy=" 0 -0 0"/>
        <visual>
            <geometry>
                <mesh filename="package://my_robot/meshes/base_link.stl"/>
            </geometry>
            <origin rpy="0 0 0" xyz="0 0 0"/>
        </visual>
        <collision>
            <geometry>
                <mesh filename="package://my_robot/meshes/base_link.stl"/>
            </geometry>
            <origin rpy="0 0 0" xyz="0 0 0.1"/>
        </collision>
        <inertial>
            <mass value="10"/>
            <inertia ixx="0.166667" ixy="0.0" ixz="0.0" iyy="0.166667" iyz="0.0" izz="0.166667"/>
            <origin rpy="0 0 0" xyz="0 0 0.05"/>
        </inertial>
    </link>

    <link name="front_left_wheel">
        <visual>
            <geometry>
                <cylinder length="0.05" radius="0.05"/>
            </geometry>
            <origin rpy="1.5707 0 0" xyz="0 0 0"/>
        </visual>
        <collision>
            <geometry>
                <cylinder length="0.05" radius="0.05"/>
            </geometry>
            <origin rpy="1.5707 0 0" xyz="0 0 0"/>
        </collision>
        <inertial>
            <mass value="5"/>
            <inertia ixx="0.14" ixy="0.0" ixz="0.0" iyy="0.14" iyz="0.0" izz="0.12"/>
            <origin rpy="1.5707 0 0" xyz="0 0 0"/>
        </inertial>
    </link>

    <link name="front_right_wheel">
        <visual>
            <geometry>
                <cylinder length="0.05" radius="0.05"/>
            </geometry>
            <origin rpy="1.5707 0 0" xyz="0 0 0"/>
        </visual>
        <collision>
            <geometry>
                <cylinder length="0.05" radius="0.05"/>
            </geometry>
            <origin rpy="1.5707 0 0" xyz="0 0 0"/>
        </collision>
        <inertial>
            <mass value="5"/>
            <inertia ixx="0.14" ixy="0.0" ixz="0.0" iyy="0.14" iyz="0.0" izz="0.12"/>
            <origin rpy="1.5707 0 0" xyz="0 0 0"/>
        </inertial>
    </link>

    <link name="back_left_wheel">
        <visual>
            <geometry>
                <cylinder length="0.05" radius="0.05"/>
            </geometry>
            <origin rpy="1.5707 0 0" xyz="0 0 0"/>
        </visual>
        <collision>
            <geometry>
                <cylinder length="0.05" radius="0.05"/>
            </geometry>
            <origin rpy="1.5707 0 0" xyz="0 0 0"/>
        </collision>
        <inertial>
            <mass value="5"/>
            <inertia ixx="0.14" ixy="0.0" ixz="0.0" iyy="0.14" iyz="0.0" izz="0.12"/>
            <origin rpy="1.5707 0 0" xyz="0 0 0"/>
        </inertial>
    </link>

    <link name="back_right_wheel">
        <visual>
            <geometry>
                <cylinder length="0.05" radius="0.05"/>
            </geometry>
            <origin rpy="1.5707 0 0" xyz="0 0 0"/>
        </visual>
        <collision>
            <geometry>
                <cylinder length="0.05" radius="0.05"/>
            </geometry>
            <origin rpy="1.5707 0 0" xyz="0 0 0"/>
        </collision>
        <inertial>
            <mass value="5"/>
            <inertia ixx="0.14" ixy="0.0" ixz="0.0" iyy="0.14" iyz="0.0" izz="0.12"/>
            <origin rpy="1.5707 0 0" xyz="0 0 0"/>
        </inertial>
    </link>

    <joint name="robot_footprint_joint" type="fixed">
        <parent link="robot_footprint"/>
        <child link="base_link"/>
        <origin xyz="0 0 0" rpy="0 0 0" />
    </joint>

    <joint name="front_left_wheel_joint" type="continuous">
        <parent link="base_link"/>
        <child link="front_left_wheel"/>
        <origin rpy="0 0 0" xyz="0.175 0.175 0.05"/>
        <axis rpy="0 0 0" xyz="0 1 0"/>
        <dynamics damping="1.0" friction="1.0"/>
        <limit effort="10000" velocity="1000"/>
    </joint>

    <joint name="front_right_wheel_joint" type="continuous">
        <parent link="base_link"/>
        <child link="front_right_wheel"/>
        <origin rpy="0 0 0" xyz="0.175 -0.175 0.05"/>
        <axis rpy="0 0 0" xyz="0 1 0"/>
        <dynamics damping="1.0" friction="1.0"/>
        <limit effort="10000" velocity="1000"/>
    </joint>

    <joint name="back_left_wheel_joint" type="continuous">
        <parent link="base_link"/>
        <child link="back_left_wheel"/>
        <origin rpy="0 0 0" xyz="-0.175 0.175 0.05"/>
        <axis rpy="0 0 0" xyz="0 1 0"/>
        <dynamics damping="1.0" friction="1.0"/>
        <limit effort="10000" velocity="1000"/>
    </joint>

    <joint name="back_right_wheel_joint" type="continuous">
        <parent link="base_link"/>
        <child link="back_right_wheel"/>
        <origin rpy="0 0 0" xyz="-0.175 -0.175 0.05"/>
        <axis rpy="0 0 0" xyz="0 1 0"/>
        <dynamics damping="1.0" friction="1.0"/>
        <limit effort="10000" velocity="1000"/>
    </joint>
    <joint name="camera_joint" type="fixed">
        <parent link="base_link"/>
        <child link="camera_link"/>
        <axis xyz="0 0 0" />
        <origin xyz="0.04 0 1.457" rpy="0 0 0"/>
    </joint>




    <!-- Camera Link -->
    <link name="camera_link">
        <collision>
            <origin xyz="0 0 0" rpy="0 0 0"/>
            <geometry>
                <mesh filename="package://my_robot/meshes/camera_link.stl"/>
            </geometry>
        </collision>
        <visual>
            <origin xyz="0 0 0" rpy="0 0 0"/>
            <geometry>
                <mesh filename="package://my_robot/meshes/camera_link.stl"/>
            </geometry>
        </visual>
        <inertial>
            <mass value="1e-5" />
            <origin xyz="0 0 0" rpy="0 0 0"/>
            <inertia ixx="1e-6" ixy="0" ixz="0" iyy="1e-6" iyz="0" izz="1e-6" />
        </inertial>
    </link>






    <!-- Ultrasonic Sensors -->
    <link name="front_ultrasonic_link">
        <collision>
            <origin xyz="0 0 0" rpy="0 0 0"/>
            <geometry>
                <mesh filename="package://my_robot/meshes/ultrasonic_front_link.stl"/>
            </geometry>
        </collision>
        <visual>
            <origin xyz="0 0 0" rpy="0 0 0"/>
            <geometry>
                <mesh filename="package://my_robot/meshes/ultrasonic_front_link.stl"/>
            </geometry>
        </visual>
        <inertial>
            <mass value="1e-5" />
            <origin xyz="0 0 0" rpy="0 0 0"/>
            <inertia ixx="1e-6" ixy="0" ixz="0" iyy="1e-6" iyz="0" izz="1e-6" />
        </inertial>
    </link>

    <joint name="front_ultrasonic_joint" type="fixed">
        <parent link="base_link"/>
        <child link="front_ultrasonic_link"/>
        <axis xyz="0 0 0" />
        <origin xyz="0 0 0" rpy="0 0 0"/>
    </joint>

    <link name="left_ultrasonic_link">
        <collision>
            <origin xyz="0 0 0" rpy="0 0 0"/>
            <geometry>
                <mesh filename="package://my_robot/meshes/ultrasonic_left_link.stl"/>
            </geometry>
        </collision>
        <visual>
            <origin xyz="0 0 0" rpy="0 0 0"/>
            <geometry>
                <mesh filename="package://my_robot/meshes/ultrasonic_left_link.stl"/>
            </geometry>
        </visual>
        <inertial>
            <mass value="1e-5" />
            <origin xyz="0 0 0" rpy="0 0 0"/>
            <inertia ixx="1e-6" ixy="0" ixz="0" iyy="1e-6" iyz="0" izz="1e-6" />
        </inertial>
    </link>

    <joint name="left_ultrasonic_joint" type="fixed">
        <parent link="base_link"/>
        <child link="left_ultrasonic_link"/>
        <axis xyz="0 0 0" />
        <origin xyz="0 0 0" rpy="0 0 0"/>
    </joint>

    <joint name="realsense_optical_joint" type="fixed">
        <origin xyz="0 0 0" rpy="-1.5707 0 -1.5707"/>
        <parent link="realsense_link"/>
        <child link="realsense_optical_link"/>
    </joint>

    <link name="realsense_optical_link">
    </link>

    <!-- Depth Camera Intel RealSense D435i -->
    <link name="realsense_link">
        <collision>
            <origin xyz="0 0 0" rpy="0 0 0"/>
            <geometry>
                <mesh filename="package://my_robot/meshes/realsense_link.stl"/>
            </geometry>
        </collision>
        <visual>
            <origin xyz="0 0 0" rpy="0 0 0"/>
            <geometry>
                <mesh filename="package://my_robot/meshes/realsense_link.stl"/>
            </geometry>
        </visual>
        <inertial>
            <mass value="1e-5" />
            <origin xyz="0 0 0" rpy="0 0 0"/>
            <inertia ixx="1e-6" ixy="0" ixz="0" iyy="1e-6" iyz="0" izz="1e-6" />
        </inertial>
    </link>

    <joint name="realsense_joint" type="fixed">
        <parent link="base_link"/>
        <child link="realsense_link"/>
        <axis xyz="0 0 0" />
        <origin xyz="0.15 0 0.675" rpy="0 0 0"/>
    </joint>

    <gazebo reference="base_link">
        <material>Gazebo/Blue</material>
    </gazebo>


</robot>
